Workbook

Sheet Zalo OA cost
A1: var_id | B1: stt | C1: item | D1: value | E1: unit | F1: data_class | G1: type | H1: year | I1: source | J1: url | K1: formula | L1: used_for
A2: cost_oa_package_annual | B2: 1.1 | C2: gói Zalo OA - tăng trưởng | D2: 2500000 | E2: VND/năm | F2: A | G2: input | H2: all | I2: Zalo OA chính thức | J2: https://oa.zalo.me/home | L2: OpEX
A3: price_zns_per_msg | B3: 1.2 | C3: đơn giá ZNS | D3: 300 | E3: VND/tin | F3: A | G3: input | H3: all | I3: Nhanh.vn | J3: https://zns.nhanh.vn/ | L3: OpEX
A4: zns_msgs_per_order | B4: 1.3 | C4: số tin ZNS/đơn | D4: 1 | E4: tin/đơn | F4: B | G4: input | H4: all | I4: Giả định | L4: OpEX
A5: cod_orders_per_month | B5: 1.4 | C5: số đơn COD/tháng | D5: ='00_Assumptions'!E7 -> 45896.76 | E5: đơn/tháng | F5: B | G5: input | H5: all | I5: Chờ GD2 | L5: OpEX
A6: zns_msgs_per_month | B6: 1.5 | C6: số tin ZNS/tháng | D6: =D5*D4 -> 45896.76 | E6: tin/tháng | F6: B | G6: formula | H6: all | I6: Suy ra | K6: cod_orders_per_month * zns_msgs_per_order | L6: OpEX
A7: zns_msgs_per_year | B7: 1.6 | C7: số tin ZNS/năm | D7: =D6*12 -> 550761.12 | E7: tin/năm | F7: B | G7: formula | H7: all | I7: Suy ra | K7: zns_msgs_per_month * 12 | L7: OpEX
A8: cost_zns_annual | B8: 1.7 | C8: chi phí ZNS/năm | D8: =D7*D3 -> 165228336 | E8: VND/năm | F8: B | G8: formula | H8: all | I8: Suy ra | K8: zns_msgs_per_year * price_zns_per_msg | L8: OpEX
A9: opex_zalo_oa_annual | B9: 1.8 | C9: tổng OpEx Zalo OA/năm | D9: =D2+D8 -> 167728336 | E9: VND/năm | F9: B | G9: derived | H9: all | I9: Suy ra | K9: cost_oa_package_annual + cost_zns_annual | L9: CF sheet

Sheet 00_Assumptions
B1: var_id | C1: group | D1: item | E1: value | F1: unit | G1: data_class | H1: source | I1: url | J1: note | K1: formula | L1: used_for | M1: year
B2: mkt_orders_per_day | C2: market | D2: tổng đơn TMDT VN/ngày | E2: 13000000 | F2: đơn/ngày | G2: A | H2: metric Q1/2026 | I2: https://vietnamfinance.vn/ | J2: 4 sàn: shopee, tiktok, lazada, tiki
B3: mkt_shopee_share | C3: market | D3: thị phần shopee | E3: 0.5604 | F3: % | G3: A | H3: metric 2025 | I3: https://www.thitruonghanghoa.com/ | J3: 56.04% doanh số
B4: mkt_cod_share | C4: market | D4: tỷ trọng COD | E4: 0.35 | F4: % | G4: A | H4: TGM Research 2025 | I4: https://tgmresearch.com/ | J4: khảo sát ntd
B5: mkt_spx_share | C5: market | D5: tỷ lệ đơn dùng SPX | E5: 0.6 | F5: % | G5: B | H5: giả định | J5: SPX xử lý ~60% đơn shopee
B6: mkt_project_scope | C6: market | D6: phạm vi pilot | E6: 0.001 | F6: % | G6: B | H6: giả định | J6: 0.1% tổng đơn COD
B7: cod_orders_per_month | C7: derived | D7: số đơn COD/tháng | E7: =E2*E3*E4*E5*E6*30 -> 45896.76 | F7: đơn/tháng | G7: B | H7: suy ra
B8: baseline_rto_rate | C8: impact | D8: tỷ lệ RTO nền | E8: 0.09 | F8: % | G8: B | H8: điểm giữa 8-10% | J8: neo cho cash inflows
B9: rto_reduction_mean | C9: impact | D9: mức giảm RTO TB | E9: 0.35 | F9: % | G9: A | H9: case study | I9: https://www.dondy.net/ | J9: tâm phân phối beta
B10: rto_reduction_std | C10: impact | D10: độ lệch chuẩn | E10: 0.1 | F10: % | G10: B | H10: giả định | J10: cho Monte Carlo
B11: project_lifetime | C11: impact | D11: vòng đời dự án | E11: 3 | F11: năm | G11: B | H11: đề cương
B12: cost_ship_per_order | C12: unit cost | D12: phí ship chiều đi | E12: 17000 | F12: VND/đơn | G12: A | H12: bảng giá SPX | I12: https://nhanh.vn/ | J12: nội tỉnh 1-2kg
B13: cost_return_ship_per_order | C13: unit cost | D13: phí chuyển hoàn | E13: 0 | F13: VND/đơn | G13: A | H13: SPX mới | I13: https://nhanh.vn/ | J13: miễn phí từ 01/01/2026
B14: cost_reclassify_per_order | C14: unit cost | D14: chi phí phân loại kho | E14: 28000 | F14: VND/đơn | G14: B | H14: suy từ lương | J14: xem nhóm labor
B15: cost_total_per_rto_order | C15: unit cost | D15: tổng chi phí 1 đơn RTO | E15: =E12+E13+E14 -> 45000 | F15: VND/đơn | G15: B | H15: suy ra | J15: 17k+28k
B16: cost_saved_per_prevented_rto | C16: unit cost | D16: chi phí tiết kiệm được mỗi đơn RTO tránh được | E16: =E13+E14 -> 28000 | F16: VND/đơn | G16: B
B17: min_wage_region1 | C17: labor | D17: lương tối thiểu vùng 1 | E17: 4960000 | F17: VND/tháng | G17: A | H17: nghị định CP
B18: working_days_per_month | C18: labor | D18: ngày làm việc/tháng | E18: 26 | F18: ngày | G18: A | H18: luật LD
B19: working_hours_per_day | C19: labor | D19: giờ làm việc/ngày | E19: 8 | F19: giờ | G19: A | H19: luật LD
B20: minutes_per_rto_order | C20: labor | D20: thời gian xử lý 1 đơn RTO | E20: 7 | F20: phút | G20: B | H20: giả định
B21: labor_overhead_rate | C21: labor | D21: hệ số chi phí gián tiếp | E21: 1.5 | F21: lần | G21: B | H21: giả định | J21: bảo hiểm, quản lý
B22: wacc | C22: financial | D22: chi phí vốn bình quân | E22: 0.1 | F22: % | G22: B | H22: lãi vay 6-7% + premium
B23: corporate_tax_rate | C23: financial | D23: thuế TNDN | E23: 0.2 | F23: % | G23: A | H23: luật thuế VN
B24: discount_rate_mc | C24: financial | D24: tỷ lệ chiết khấu MC | E24: 0.1 | F24: % | G24: B | H24: wacc
A25: Nhóm A: Cfo (vốn đầu tư ban đầu) | B25: cf0_ai_dev_cost | C25: cf0 | D25: chi phí phát triển AI | E25: 600000000 | F25: VND | G25: B | H25: team 4 người x 30tr/tháng x 4 tháng+hạ tầng
B26: cf0_integration_cost | C26: cf0 | D26: chi phí tích hợp API | E26: 50000000 | F26: VND | G26: B | H26: tích hợp Zalo OA+hệ thống đơn hàng
B27: cf0_training_cost | C27: cf0 | D27: chi phí đào tạo shipper | E27: 30000000 | F27: VND | G27: B | H27: 500 shipper x 60k/người
B28: cf0_total | C28: cf0 | D28: tổng vốn đầu tư ban đầu | E28: =SUM(E25:E27) -> 680000000 | F28: VND | G28: B | H28: sum 3 cái trên
A29: Nhóm B: Dòng tiền | B29: rto_orders_baseline | C29: cash_flow | D29: số đơn RTO/nằm ở baseline | E29: =E7*E8*12 -> 49568.501 | F29: đơn/năm | G29: B
B30: rto_orders_prevented | C30: cash_flow | D30: số đơn RTO giảm được/năm | E30: =E29*E9 -> 17348.975 | F30: đơn/năm | G30: B
B31: cash_inflow_annual | C31: cash_flow | D31: cash inflow/năm | E31: =E16*E30 -> 4.8577131e+08 | F31: VND/năm | G31: B
A32: Nhóm C: Giả định tăng trưởng | B32: order_growth_rate | C32: growth | D32: tăng trưởng đơn hàng/năm | E32: 0.15 | F32: % | G32: B | J32: TMDT VN tăng ~15-20%/năm
B33: opex_growth_rate | C33: growth | D33: tăng trưởng OpEx/năm | E33: 0.05 | F33: % | G33: B | J33: lạm phát + tăng quy mô
B34: salvage_value_rate | C34: growth | D34: Giá trị thanh lý cuối dự án | E34: 0.1 | F34: % | G34: B | J34: % của Cfo
A35: Nhóm D: Tham số phân phối Monte Carlo | B35: beta_alpha | C35: monte_carlo | D35: tham số alpha của Beta | E35: =E9*((E9*(1-E9)/E10^2)-1) -> 7.6125 | G35: B | J35: alpha=meanx((meanx(1-mean)/std^2)-1)
B36: beta_beta | C36: monte_carlo | D36: tham số beta của Beta | E36: =(1-E9)*((E9*(1-E9)/E10^2)-1) -> 14.1375 | G36: B | J36: beta=(1-mean)x((meanx(1-mean)/std^2)-1
B37: order_volume_std | C37: monte_carlo | D37: độ lệch chuẩn quy mô đơn | E37: 0.1 | F37: % | G37: B | J37: cho normal distribution
B38: mc_iterations | C38: monte_carlo | D38: số kịch bản Monte Carlo | E38: 1000 | F38: lần | G38: B | J38: 1000 kịch bản monte carlo
A39: Nhóm E: Thuế và dòng tiền sau thuế | B39: depreciation_years | C39: tax_depreciation | D39: số năm khấu hao Cfo | E39: 3 | F39: năm | G39: B | J39: khấu hao đều
B40: depreciation_annual | C40: tax_depreciation | D40: khấu hao hàng năm | E40: =E28/E39 -> 2.2666667e+08 | F40: VND/năm | G40: B
...

Sheet 03_CashFlow
A1: STT | B1: Chỉ tiêu | C1: Year 0 | D1: Year 1 | E1: Year 2 | F1: Year 3
A2: 1 | B2: Cash Inflows
A3: 2 | B3: số đơn COD/tháng | D3: ='00_Assumptions'!E7 -> 45896.76 | E3: =D3*(1+'00_Assumptions'!E32) -> 52781.274 | F3: =E3*(1+'00_Assumptions'!E32) -> 60698.465
A4: 3 | B4: số đơn RTO baseline/năm | D4: =D3*'00_Assumptions'!E8*12 -> 49568.501 | E4: =E3* '00_Assumptions'!E8*12 -> 57003.776 | F4: =F3*'00_Assumptions'!E8*12 -> 65554.342
A5: 4 | B5: số đơn RTO giảm được/năm | D5: =D4*'00_Assumptions'!E9 -> 17348.975 | E5: =E4*'00_Assumptions'!E9 -> 19951.322 | F5: =F4*'00_Assumptions'!E9 -> 22944.02
A6: 5 | B6: chi phí tiết kiệm/đơn | D6: ='00_Assumptions'!E16 -> 28000 | E6: ='00_Assumptions'!E16 -> 28000 | F6: ='00_Assumptions'!E16 -> 28000
A7: 6 | B7: tổng Cash Inflow | D7: =D5*D6 -> 4.8577131e+08 | E7: =E5*E6 -> 5.58637e+08 | F7: =F5*F6 -> 6.4243255e+08
A8: 7 | B8: OpEx
A9: 8 | B9: OpEx Zalo OA | D9: ='Zalo OA cost'!D9 -> 167728336 | E9: =D9*(1+'00_Assumptions'!E33) -> 1.7611475e+08 | F9: =E9*(1+'00_Assumptions'!E33) -> 1.8492049e+08
A10: 9 | B10: EBIT | D10: =D7-D9-D11 -> 91376305 | E10: =E7-E9-E11 -> 1.5585558e+08 | F10: =F7-F9-F11 -> 2.308454e+08
A11: 10 | B11: khấu hao | D11: ='00_Assumptions'!E40 -> 2.2666667e+08 | E11: ='00_Assumptions'!E40 -> 2.2666667e+08 | F11: ='00_Assumptions'!E40 -> 2.2666667e+08
A12: 11 | B12: EBT(lợi nhuận trước thuế) | D12: =D10 -> 91376305 | E12: =E10 -> 1.5585558e+08 | F12: =F10 -> 2.308454e+08
A13: 12 | B13: thuế TNDN(20%) | D13: =MAX(0,D12)*'00_Assumptions'!E23 -> 18275261 | E13: =MAX(0,E12)*'00_Assumptions'!E23 -> 31171117 | F13: =MAX(0,F12)*'00_Assumptions'!E23 -> 46169080
A14: 13 | B14: lợi nhuận sau thuế | D14: =D12-D13 -> 73101044 | E14: =E12-E13 -> 1.2468447e+08 | F14: =F12-F13 -> 1.8467632e+08
A15: 14 | B15: cộng lại khấu hao | D15: =D11 -> 2.2666667e+08 | E15: =E11 -> 2.2666667e+08 | F15: =F11 -> 2.2666667e+08
A16: 15 | B16: Net Cash Flow | C16: =-'00_Assumptions'!E28 -> -680000000 | D16: =D14+D15 -> 2.9976771e+08 | E16: =E14+E15 -> 3.5135113e+08 | F16: =F14+F15 -> 4.1134298e+08
A17: 16 | B17: Cumulative CF | C17: =C16 -> -680000000 | D17: =C17+D16 -> -3.8023229e+08 | E17: =D17+E16 -> -28881155 | F17: =E17+F16 -> 3.8246183e+08
A18: 17 | B18: Discounted CF(WACC 10%) | C18: =C16 -> -680000000 | D18: =D16/(1+'00_Assumptions'!E22)^1 -> 2.725161e+08 | E18: =E16/(1+'00_Assumptions'!E22)^2 -> 2.9037284e+08 | F18: =F16/(1+'00_Assumptions'!E22)^3 -> 3.0904807e+08
A19: 18 | B19: Cumulative Discounted CF | C19: =C18 -> -680000000 | D19: =C19+D18 -> -4.074839e+08 | E19: =D19+E18 -> -1.1711106e+08 | F19: =E19+F18 -> 1.9193701e+08
B21: NPV | C21: =C16+NPV('00_Assumptions'!E22,D16:F16) -> 1.9193701e+08
B22: IRR | C22: =IRR(C16:F16) -> 0.24556713
B23: Payback | C23: =2+ABS(E17)/F16 -> 2.0702119
